<?xml version="1.0" encoding="utf-8"?>
<!-- This URDF was automatically created by SolidWorks to URDF Exporter! Originally created by Stephen Brawner (brawner@gmail.com) 
     Commit Version: 1.5.1-0-g916b5db  Build Version: 1.5.7152.31018
     For more information, please see http://wiki.ros.org/sw_urdf_exporter -->
<robot
  name="b1">
  <link
    name="base_link">
    <inertial>
      <origin
        xyz="-0.00058348 -3.6892E-07 0.098631"
        rpy="0 0 0" />
      <mass
        value="25.4" />
      <inertia
        ixx="0.13869"
        ixy="1.1602E-08"
        ixz="1.1583E-06"
        iyy="0.10486"
        iyz="3.1009E-07"
        izz="0.075742" />
    </inertial>
    <visual>
      <origin
        xyz="0 0 0"
        rpy="0 0 0" />
      <geometry>
        <mesh
          filename="../meshes/base_link.STL" />
      </geometry>
      <material
        name="">
        <color
          rgba="0.65098 0.61961 0.58824 1" />
      </material>
    </visual>
    <collision>
      <origin
        xyz="0 0 0"
        rpy="0 0 0" />
      <geometry>
        <mesh
          filename="../meshes/base_link.STL" />
      </geometry>
    </collision>
  </link>
  <link
    name="ll1">
    <inertial>
      <origin
        xyz="0.0203 0.0203 -0.021882"
        rpy="0 0 0" />
      <mass
        value="1.73" />
      <inertia
        ixx="0.00064365"
        ixy="-1.4079E-10"
        ixz="7.1641E-05"
        iyy="0.00040381"
        iyz="1.47E-10"
        izz="0.00057925" />
    </inertial>
    <visual>
      <origin
        xyz="0 0 0"
        rpy="0 0 0" />
      <geometry>
        <mesh
          filename="../meshes/ll1.STL" />
      </geometry>
      <material
        name="">
        <color
          rgba="0.65098 0.61961 0.58824 1" />
      </material>
    </visual>
    <collision>
      <origin
        xyz="0 0 0"
        rpy="0 0 0" />
      <geometry>
        <mesh
          filename="../meshes/ll1.STL" />
      </geometry>
    </collision>
  </link>
  <joint
    name="left_leg_hip_roll"
    type="revolute">
    <origin
      xyz="-0.055306 0.0925 -0.043"
      rpy="0 0 0" />
    <parent
      link="base_link" />
    <child
      link="ll1" />
    <axis
      xyz="-1 0 0" />
    <limit
      lower="-1.57"
      upper="0.17"
      effort="60"
      velocity="3.14" />
  </joint>
  <link
    name="ll2">
    <inertial>
      <origin
        xyz="-0.011966 -9.5758E-09 -0.023875"
        rpy="0 0 0" />
      <mass
        value="0.55" />
      <inertia
        ixx="0.00030663"
        ixy="-2.1702E-11"
        ixz="-2.2996E-05"
        iyy="0.00020556"
        iyz="-4.7854E-11"
        izz="0.00040354" />
    </inertial>
    <visual>
      <origin
        xyz="0 0 0"
        rpy="0 0 0" />
      <geometry>
        <mesh
          filename="../meshes/ll2.STL" />
      </geometry>
      <material
        name="">
        <color
          rgba="0.65098 0.61961 0.58824 1" />
      </material>
    </visual>
    <collision>
      <origin
        xyz="0 0 0"
        rpy="0 0 0" />
      <geometry>
        <mesh
          filename="../meshes/ll2.STL" />
      </geometry>
    </collision>
  </link>
  <joint
    name="left_leg_hip_yaw"
    type="revolute">
    <origin
      xyz="0.0540088169698284 0 -0.0425"
      rpy="0 0 0" />
    <parent
      link="ll1" />
    <child
      link="ll2" />
    <axis
      xyz="0 0 1" />
    <limit
      lower="-0.79"
      upper="0.79"
      effort="33"
      velocity="3.14" />
  </joint>
  <link
    name="ll3">
    <inertial>
      <origin
        xyz="0.01087 -4.44E-05 -0.18406"
        rpy="0 0 0" />
      <mass
        value="5.049" />
      <inertia
        ixx="0.23235"
        ixy="3E-06"
        ixz="-0.02299"
        iyy="0.23924"
        iyz="-2E-05"
        izz="0.011741" />
    </inertial>
    <visual>
      <origin
        xyz="0 0 0"
        rpy="0 0 0" />
      <geometry>
        <mesh
          filename="../meshes/ll3.STL" />
      </geometry>
      <material
        name="">
        <color
          rgba="0.89804 0.91765 0.92941 1" />
      </material>
    </visual>
    <collision>
      <origin
        xyz="0 0 0"
        rpy="0 0 0" />
      <geometry>
        <mesh
          filename="../meshes/ll3.STL" />
      </geometry>
    </collision>
  </link>
  <joint
    name="left_leg_hip_pitch"
    type="revolute">
    <origin
      xyz="0 0 -0.0455"
      rpy="0 0 0" />
    <parent
      link="ll2" />
    <child
      link="ll3" />
    <axis
      xyz="0 -1 0" />
    <limit
      lower="-1.4"
      upper="0.34"
      effort="300"
      velocity="3.14" />
  </joint>
  <link
    name="ll4">
    <inertial>
      <origin
        xyz="-0.0029 -0.00028 -0.231"
        rpy="0 0 0" />
      <mass
        value="1.993" />
      <inertia
        ixx="0.13785"
        ixy="1.1E-06"
        ixz="0.002653"
        iyy="0.13792"
        iyz="1E-05"
        izz="0.001226" />
    </inertial>
    <visual>
      <origin
        xyz="0 0 0"
        rpy="0 0 0" />
      <geometry>
        <mesh
          filename="../meshes/ll4.STL" />
      </geometry>
      <material
        name="">
        <color
          rgba="0.89804 0.91765 0.92941 1" />
      </material>
    </visual>
    <collision>
      <origin
        xyz="0 0 0"
        rpy="0 0 0" />
      <geometry>
        <mesh
          filename="../meshes/ll4.STL" />
      </geometry>
    </collision>
  </link>
  <joint
    name="left_knee"
    type="revolute">
    <origin
      xyz="0 0 -0.3596"
      rpy="0 0 0" />
    <parent
      link="ll3" />
    <child
      link="ll4" />
    <axis
      xyz="0 1 0" />
    <limit
      lower="0"
      upper="1.4"
      effort="300"
      velocity="3.14" />
  </joint>
  <link
    name="ll5">
    <inertial>
      <origin
        xyz="0.0296 -0.002 -0.034"
        rpy="0 0 0" />
      <mass
        value="1.118" />
      <inertia
        ixx="0.000587"
        ixy="-5E-05"
        ixz="-0.000397"
        iyy="0.005066"
        iyz="8.3E-05"
        izz="0.00537" />
    </inertial>
    <visual>
      <origin
        xyz="0 0 0"
        rpy="0 0 0" />
      <geometry>
        <mesh
          filename="../meshes/ll5.STL" />
      </geometry>
      <material
        name="">
        <color
          rgba="0.89804 0.91765 0.92941 1" />
      </material>
    </visual>
    <collision>
      <origin
        xyz="0 0 0"
        rpy="0 0 0" />
      <geometry>
        <mesh
          filename="../meshes/ll5.STL" />
      </geometry>
    </collision>
  </link>
  <joint
    name="left_leg_ank_pitch"
    type="revolute">
    <origin
      xyz="0.015 0 -0.44"
      rpy="0 0 0" />
    <parent
      link="ll4" />
    <child
      link="ll5" />
    <axis
      xyz="0 1 0" />
    <limit
      lower="-0.87"
      upper="0.87"
      effort="50"
      velocity="3.14" />
  </joint>
  <link
    name="rl1">
    <inertial>
      <origin
        xyz="0.0203 0.0203 -0.021882"
        rpy="0 0 0" />
      <mass
        value="1.73" />
      <inertia
        ixx="0.00064365"
        ixy="-1.4079E-10"
        ixz="7.1641E-05"
        iyy="0.00040381"
        iyz="1.47E-10"
        izz="0.00057925" />
    </inertial>
    <visual>
      <origin
        xyz="0 0 0"
        rpy="0 0 0" />
      <geometry>
        <mesh
          filename="../meshes/rl1.STL" />
      </geometry>
      <material
        name="">
        <color
          rgba="1 1 1 1" />
      </material>
    </visual>
    <collision>
      <origin
        xyz="0 0 0"
        rpy="0 0 0" />
      <geometry>
        <mesh
          filename="../meshes/rl1.STL" />
      </geometry>
    </collision>
  </link>
  <joint
    name="right_leg_hip_roll"
    type="revolute">
    <origin
      xyz="-0.0553058169698284 -0.0925 -0.043"
      rpy="0 0 0" />
    <parent
      link="base_link" />
    <child
      link="rl1" />
    <axis
      xyz="-1 0 0" />
    <limit
      lower="-0.17"
      upper="1.57"
      effort="60"
      velocity="3.14" />
  </joint>
  <link
    name="rl2">
    <inertial>
      <origin
        xyz="-0.011966 -9.5758E-09 -0.023875"
        rpy="0 0 0" />
      <mass
        value="0.55" />
      <inertia
        ixx="0.00030663"
        ixy="-2.1702E-11"
        ixz="-2.2996E-05"
        iyy="0.00020556"
        iyz="-4.7854E-11"
        izz="0.00040354" />
    </inertial>
    <visual>
      <origin
        xyz="0 0 0"
        rpy="0 0 0" />
      <geometry>
        <mesh
          filename="../meshes/rl2.STL" />
      </geometry>
      <material
        name="">
        <color
          rgba="0.65098 0.61961 0.58824 1" />
      </material>
    </visual>
    <collision>
      <origin
        xyz="0 0 0"
        rpy="0 0 0" />
      <geometry>
        <mesh
          filename="../meshes/rl2.STL" />
      </geometry>
    </collision>
  </link>
  <joint
    name="right_leg_hip_yaw"
    type="revolute">
    <origin
      xyz="0.0540088169698284 0 -0.0425"
      rpy="0 0 0" />
    <parent
      link="rl1" />
    <child
      link="rl2" />
    <axis
      xyz="0 0 1" />
    <limit
      lower="-0.79"
      upper="0.79"
      effort="33"
      velocity="3.14" />
  </joint>
  <link
    name="rl3">
    <inertial>
      <origin
        xyz="0.01087 -4.44E-05 -0.19733"
        rpy="0 0 0" />
      <mass
        value="5.049" />
      <inertia
        ixx="0.23235"
        ixy="3E-06"
        ixz="-0.02299"
        iyy="0.23924"
        iyz="-2E-05"
        izz="0.011741" />
    </inertial>
    <visual>
      <origin
        xyz="0 0 0"
        rpy="0 0 0" />
      <geometry>
        <mesh
          filename="../meshes/rl3.STL" />
      </geometry>
      <material
        name="">
        <color
          rgba="0.89804 0.91765 0.92941 1" />
      </material>
    </visual>
    <collision>
      <origin
        xyz="0 0 0"
        rpy="0 0 0" />
      <geometry>
        <mesh
          filename="../meshes/rl3.STL" />
      </geometry>
    </collision>
  </link>
  <joint
    name="right_leg_hip_pitch"
    type="revolute">
    <origin
      xyz="0 0 -0.0455000000000001"
      rpy="0 0 0" />
    <parent
      link="rl2" />
    <child
      link="rl3" />
    <axis
      xyz="0 -1 0" />
    <limit
      lower="-1.4"
      upper="0.34"
      effort="300"
      velocity="3.14" />
  </joint>
  <link
    name="rl4">
    <inertial>
      <origin
        xyz="-0.0029 -0.00028 -0.231"
        rpy="0 0 0" />
      <mass
        value="1.993" />
      <inertia
        ixx="0.13785"
        ixy="1.1E-06"
        ixz="0.002653"
        iyy="0.13792"
        iyz="1E-05"
        izz="0.001226" />
    </inertial>
    <visual>
      <origin
        xyz="0 0 0"
        rpy="0 0 0" />
      <geometry>
        <mesh
          filename="../meshes/rl4.STL" />
      </geometry>
      <material
        name="">
        <color
          rgba="0.89804 0.91765 0.92941 1" />
      </material>
    </visual>
    <collision>
      <origin
        xyz="0 0 0"
        rpy="0 0 0" />
      <geometry>
        <mesh
          filename="../meshes/rl4.STL" />
      </geometry>
    </collision>
  </link>
  <joint
    name="right_knee"
    type="revolute">
    <origin
      xyz="0 0 -0.3596"
      rpy="0 0 0" />
    <parent
      link="rl3" />
    <child
      link="rl4" />
    <axis
      xyz="0 1 0" />
    <limit
      lower="0"
      upper="1.4"
      effort="300"
      velocity="3.14" />
  </joint>
  <link
    name="rl5">
    <inertial>
      <origin
        xyz="0.0296 -0.002 -0.034"
        rpy="0 0 0" />
      <mass
        value="1.118" />
      <inertia
        ixx="0.000587"
        ixy="-5E-05"
        ixz="-0.000397"
        iyy="0.005066"
        iyz="8.3E-05"
        izz="0.00537" />
    </inertial>
    <visual>
      <origin
        xyz="0 0 0"
        rpy="0 0 0" />
      <geometry>
        <mesh
          filename="../meshes/rl5.STL" />
      </geometry>
      <material
        name="">
        <color
          rgba="0.89804 0.91765 0.92941 1" />
      </material>
    </visual>
    <collision>
      <origin
        xyz="0 0 0"
        rpy="0 0 0" />
      <geometry>
        <mesh
          filename="../meshes/rl5.STL" />
      </geometry>
    </collision>
  </link>
  <joint
    name="right_leg_ank_pitch"
    type="revolute">
    <origin
      xyz="0.0149999999999999 0 -0.44"
      rpy="0 0 0" />
    <parent
      link="rl4" />
    <child
      link="rl5" />
    <axis
      xyz="0 -1 0" />
    <limit
      lower="-0.87"
      upper="0.87"
      effort="50"
      velocity="3.14" />
  </joint>
</robot>
